<?xml version="1.0" encoding="utf-8"?>

<robot name="sentry_chassis"   xmlns:xacro="http://www.ros.org/wiki/xacro">
<link
    name="base_link">
    <inertial>
      <origin
        xyz="0.00225297070027259 0.0021561284245786 0.0235031309630918"
        rpy="0 0 0" />
      <mass
        value="4.42503101633294" />
      <inertia
        ixx="0.0160955362042838"
        ixy="-4.37751798666585E-07"
        ixz="-3.76131129209663E-05"
        iyy="0.00951260621260376"
        iyz="-1.23241554900005E-05"
        izz="0.0235407659569457" />
    </inertial>
    <visual>
      <origin
        xyz="0 0 0"
        rpy="0 0 0" />
      <geometry>
        <mesh
          filename="package://sentry9/meshes/base_link.STL" />
      </geometry>
      <material
        name="">
        <color
          rgba="1 1 1 1" />
      </material>
    </visual>
    <collision>
      <origin
        xyz="0 0 0"
        rpy="0 0 0" />
      <geometry>
        <mesh
          filename="package://sentry9/meshes/base_link.STL" />
      </geometry>
    </collision>
  </link>

<link name="base_footprint">
   </link>

  <joint
    name="footprint2baselink"
    type="fixed">
    <origin
      xyz="0 0 0.5"
      rpy="0 0 0" />
    <parent
      link="base_footprint" />
    <child
      link="base_link" />
  </joint>



  <link
    name="Heading_Left_Front_Link">
    <inertial>
      <origin
        xyz="0.000327088899147732 0.00203413083857223 -0.0346740035294639"
        rpy="0 0 0" />
      <mass
        value="0.70269597713817" />
      <inertia
        ixx="0.000344054568245934"
        ixy="1.44356624989042E-05"
        ixz="4.30992500251002E-07"
        iyy="0.000434102546909307"
        iyz="3.89337584122031E-07"
        izz="0.000452885587921925" />
    </inertial>
    <visual>
      <origin
        xyz="0 0 0"
        rpy="0 0 0" />
      <geometry>
        <mesh
          filename="package://sentry9/meshes/Heading_Left_Front_Link.STL" />
      </geometry>
      <material
        name="">
        <color
          rgba="0.203921568627451 0.203921568627451 0.203921568627451 1" />
      </material>
    </visual>
    <collision>
      <origin
        xyz="0 0 0"
        rpy="0 0 0" />
      <geometry>
        <mesh
          filename="package://sentry9/meshes/Heading_Left_Front_Link.STL" />
      </geometry>
    </collision>
  </link>
  <joint
    name="Heading_Left_Front_Joint"
    type="continuous">
    <origin
      xyz="0.178 0.178 0.042"
      rpy="0 0 0" />
    <parent
      link="base_link" />
    <child
      link="Heading_Left_Front_Link" />
    <axis
      xyz="0 0 1" />
  </joint>
  <link
    name="Driving_Left_Front_Link">
    <inertial>
      <origin
        xyz="-0.00614745666963601 -0.0410307142735137 -7.63278329429795E-17"
        rpy="0 0 0" />
      <mass
        value="0.2729799494341" />
      <inertia
        ixx="0.000310662933362954"
        ixy="4.06306257516411E-05"
        ixz="1.84256237395161E-19"
        iyy="0.000575761324526438"
        iyz="5.90527327364396E-19"
        izz="0.000304575420247696" />
    </inertial>
    <visual>
      <origin
        xyz="0 0 0"
        rpy="0 0 0" />
      <geometry>
        <mesh
          filename="package://sentry9/meshes/Driving_Left_Front_Link.STL" />
      </geometry>
      <material
        name="">
        <color
          rgba="0.498039215686275 0.498039215686275 0.498039215686275 1" />
      </material>
    </visual>
    <collision>
      <origin
        xyz="0 0 0"
        rpy="0 0 0" />
      <geometry>
        <mesh
          filename="package://sentry9/meshes/Driving_Left_Front_Link.STL" />
      </geometry>
    </collision>
  </link>
  <joint
    name="Driving_Left_Front_Joint"
    type="revolute">
    <origin
      xyz="0.0062232 0.041536 -0.0993"
      rpy="0 0 0" />
    <parent
      link="Heading_Left_Front_Link" />
    <child
      link="Driving_Left_Front_Link" />
    <axis
      xyz="-0.14817 -0.98896 0" />
    <limit lower="-1e9" upper="1e9" effort="10" velocity="70" />
  </joint>
  <link
    name="Heading_Left_Back_link">
    <inertial>
      <origin
        xyz="-0.00185369374070293 0.000300550149383016 -0.0339698001150252"
        rpy="0 0 0" />
      <mass
        value="0.687442415270207" />
      <inertia
        ixx="0.00043445619263871"
        ixy="-1.39837821126049E-05"
        ixz="-3.89337541412287E-07"
        iyy="0.000347356550512787"
        iyz="4.30992933776622E-07"
        izz="0.000463291748719571" />
    </inertial>
    <visual>
      <origin
        xyz="0 0 0"
        rpy="0 0 0" />
      <geometry>
        <mesh
          filename="package://sentry9/meshes/Heading_Left_Back_link.STL" />
      </geometry>
      <material
        name="">
        <color
          rgba="0.203921568627451 0.203921568627451 0.203921568627451 1" />
      </material>
    </visual>
    <collision>
      <origin
        xyz="0 0 0"
        rpy="0 0 0" />
      <geometry>
        <mesh
          filename="package://sentry9/meshes/Heading_Left_Back_link.STL" />
      </geometry>
    </collision>
  </link>
  <joint
    name="Heading_Left_Back_Joint"
    type="continuous">
    <origin
      xyz="-0.178 0.178 0.042"
      rpy="0 0 0" />
    <parent
      link="base_link" />
    <child
      link="Heading_Left_Back_link" />
    <axis
      xyz="0 0 1" />
  </joint>
  <link
    name="Driving_Left_back_Link">
    <inertial>
      <origin
        xyz="0.0410307142735137 -0.00614745666963609 0"
        rpy="0 0 0" />
      <mass
        value="0.2729799494341" />
      <inertia
        ixx="0.000575761324526438"
        ixy="-4.06306257516413E-05"
        ixz="1.01045361243015E-19"
        iyy="0.000310662933362954"
        iyz="1.7382100922574E-19"
        izz="0.000304575420247696" />
    </inertial>
    <visual>
      <origin
        xyz="0 0 0"
        rpy="0 0 0" />
      <geometry>
        <mesh
          filename="package://sentry9/meshes/Driving_Left_back_Link.STL" />
      </geometry>
      <material
        name="">
        <color
          rgba="0.698039215686274 0.698039215686274 0.698039215686274 1" />
      </material>
    </visual>
    <collision>
      <origin
        xyz="0 0 0"
        rpy="0 0 0" />
      <geometry>
        <mesh
          filename="package://sentry9/meshes/Driving_Left_back_Link.STL" />
      </geometry>
    </collision>
  </link>

  <joint
    name="Driving_Left_back_Joint"
    type="revolute">
    <origin
      xyz="-0.041536 0.0062232 -0.0993"
      rpy="0 0 0" />
    <parent
      link="Heading_Left_Back_link" />
    <child
      link="Driving_Left_back_Link" />
    <axis
      xyz="0.98896 -0.14817 0" />
    <limit lower="-1e9" upper="1e9" effort="10" velocity="70" />
  </joint>
  <link
    name="Heading_Right_Front_link">
    <inertial>
      <origin
        xyz="0.00185369374329517 -0.000300550147229545 -0.0339698001040521"
        rpy="0 0 0" />
      <mass
        value="0.68744241513136" />
      <inertia
        ixx="0.000434456192641999"
        ixy="-1.39837821131444E-05"
        ixz="3.89337547879156E-07"
        iyy="0.000347356550518619"
        iyz="-4.30992936777688E-07"
        izz="0.000463291748721908" />
    </inertial>
    <visual>
      <origin
        xyz="0 0 0"
        rpy="0 0 0" />
      <geometry>
        <mesh
          filename="package://sentry9/meshes/Heading_Right_Front_link.STL" />
      </geometry>
      <material
        name="">
        <color
          rgba="0.333333333333333 0.333333333333333 0.333333333333333 1" />
      </material>
    </visual>
    <collision>
      <origin
        xyz="0 0 0"
        rpy="0 0 0" />
      <geometry>
        <mesh
          filename="package://sentry9/meshes/Heading_Right_Front_link.STL" />
      </geometry>
    </collision>
  </link>
  <joint
    name="Heading_Right_Front_Joint"
    type="continuous">
    <origin
      xyz="0.178 -0.178 0.042"
      rpy="0 0 0" />
    <parent
      link="base_link" />
    <child
      link="Heading_Right_Front_link" />
    <axis
      xyz="0 0 1" />
  </joint>
  <link
    name="Driving_Right_Front_Link">
    <inertial>
      <origin
        xyz="-0.0410307142735136 0.00614745666963606 3.33066907387547E-16"
        rpy="0 0 0" />
      <mass
        value="0.2729799494341" />
      <inertia
        ixx="0.000575761324526438"
        ixy="-4.06306257516409E-05"
        ixz="-2.126475495238E-18"
        iyy="0.000310662933362954"
        iyz="2.86832817431728E-19"
        izz="0.000304575420247696" />
    </inertial>
    <visual>
      <origin
        xyz="0 0 0"
        rpy="0 0 0" />
      <geometry>
        <mesh
          filename="package://sentry9/meshes/Driving_Right_Front_Link.STL" />
      </geometry>
      <material
        name="">
        <color
          rgba="0.698039215686274 0.698039215686274 0.698039215686274 1" />
      </material>
    </visual>
    <collision>
      <origin
        xyz="0 0 0"
        rpy="0 0 0" />
      <geometry>
        <mesh
          filename="package://sentry9/meshes/Driving_Right_Front_Link.STL" />
      </geometry>
    </collision>
  </link>
  <joint
    name="Driving_Right_Front_Joint"
    type="revolute">
    <origin
      xyz="0.041536 -0.0062232 -0.0993"
      rpy="0 0 0" />
    <parent
      link="Heading_Right_Front_link" />
    <child
      link="Driving_Right_Front_Link" />
    <axis
      xyz="-0.98896 0.14817 0" />
    <limit lower="-1e9" upper="1e9" effort="10" velocity="70" />
  </joint>
  <link
    name="Heading_Right_Back_Link">
    <inertial>
      <origin
        xyz="-0.000280515778898149 -0.00171859968040594 -0.0337632364190828"
        rpy="0 0 0" />
      <mass
        value="0.68527429688982" />
      <inertia
        ixx="0.000347240930609659"
        ixy="1.39806628441215E-05"
        ixz="-4.30009078204328E-07"
        iyy="0.000434319886217517"
        iyz="-3.89435384002671E-07"
        izz="0.000463176588814637" />
    </inertial>
    <visual>
      <origin
        xyz="0 0 0"
        rpy="0 0 0" />
      <geometry>
        <mesh
          filename="package://sentry9/meshes/Heading_Right_Back_Link.STL" />
      </geometry>
      <material
        name="">
        <color
          rgba="0.203921568627451 0.203921568627451 0.203921568627451 1" />
      </material>
    </visual>
    <collision>
      <origin
        xyz="0 0 0"
        rpy="0 0 0" />
      <geometry>
        <mesh
          filename="package://sentry9/meshes/Heading_Right_Back_Link.STL" />
      </geometry>
    </collision>
  </link>
  <joint
    name="Heading_Right_Back_Joint"
    type="continuous">
    <origin
      xyz="-0.178 -0.178 0.042"
      rpy="0 0 0" />
    <parent
      link="base_link" />
    <child
      link="Heading_Right_Back_Link" />
    <axis
      xyz="0 0 1" />
  </joint>
  <link
    name="Driving_Right_Back_Link">
    <inertial>
      <origin
        xyz="0.00614745666963606 0.0410307142735137 2.15105711021124E-16"
        rpy="0 0 0" />
      <mass
        value="0.2729799494341" />
      <inertia
        ixx="0.000310662933362954"
        ixy="4.0630625751641E-05"
        ixz="1.63280924992022E-19"
        iyy="0.000575761324526438"
        iyz="1.32618806047301E-18"
        izz="0.000304575420247696" />
    </inertial>
    <visual>
      <origin
        xyz="0 0 0"
        rpy="0 0 0" />
      <geometry>
        <mesh
          filename="package://sentry9/meshes/Driving_Right_Back_Link.STL" />
      </geometry>
      <material
        name="">
        <color
          rgba="0.698039215686274 0.698039215686274 0.698039215686274 1" />
      </material>
    </visual>
    <collision>
      <origin
        xyz="0 0 0"
        rpy="0 0 0" />
      <geometry>
        <mesh
          filename="package://sentry9/meshes/Driving_Right_Back_Link.STL" />
      </geometry>
    </collision>
  </link>
  <joint
    name="Driving_Right_Back_Joint"
    type="revolute">
    <origin
      xyz="-0.0062232 -0.041536 -0.0993"
      rpy="0 0 0" />
    <parent
      link="Heading_Right_Back_Link" />
    <child
      link="Driving_Right_Back_Link" />
    <axis
      xyz="0.14817 0.98896 0" />
    <limit lower="-1e9" upper="1e9" effort="10" velocity="70" />
  </joint>

  <xacro:macro name="joint_transmission" params="prefix">
    <transmission name="trans_${prefix}">
      <type>transmission_interface/SimpleTransmission</type>
      <actuator name="${prefix}_actuator">
        <mechanicalReduction>1</mechanicalReduction>
      </actuator>
      <joint name="${prefix}_Joint">
        <hardwareInterface>hardware_interface/EffortJointInterface</hardwareInterface>
      </joint>
    </transmission>
  </xacro:macro>

<!-- transmission for left_back_wheel-->
  <xacro:joint_transmission prefix="Heading_Left_Back"/>
  <xacro:joint_transmission prefix="Driving_Left_back"/>

<!-- transmission for right_back_wheel-->
  <xacro:joint_transmission prefix="Heading_Left_Front"/>
  <xacro:joint_transmission prefix="Driving_Left_Front"/>

<!-- transmission for right_front_wheel-->
  <xacro:joint_transmission prefix="Heading_Right_Front"/>
  <xacro:joint_transmission prefix="Driving_Right_Front"/>

<!-- transmission for left_front_wheel -->
  <xacro:joint_transmission prefix="Heading_Right_Back"/>
  <xacro:joint_transmission prefix="Driving_Right_Back"/>

 <gazebo reference="base_link">
     <material>Gazebo/Grey</material>
     <turnGravityOff>false</turnGravityOff>
 </gazebo>

   <gazebo reference="Heading_Left_Front_Link">
     <material>Gazebo/White</material>
     <turnGravityOff>false</turnGravityOff>
 </gazebo>

   <gazebo reference="Heading_Left_Back_Link">
     <material>Gazebo/White</material>
     <turnGravityOff>false</turnGravityOff>
 </gazebo>

   <gazebo reference="Heading_Right_Front_Link">
     <material>Gazebo/White</material>
     <turnGravityOff>false</turnGravityOff>
 </gazebo>

   <gazebo reference="Heading_Right_Back_Link">
     <material>Gazebo/White</material>
     <turnGravityOff>false</turnGravityOff>
 </gazebo>

   <gazebo reference="Driving_Left_Front_Link">
     <material>Gazebo/Grey</material>
     <turnGravityOff>false</turnGravityOff>
 </gazebo>

   <gazebo reference="Driving_Left_back_Link">
     <material>Gazebo/Grey</material>
     <turnGravityOff>false</turnGravityOff>
 </gazebo>

    <gazebo reference="Driving_Right_Front_Link">
     <material>Gazebo/Grey</material>
     <turnGravityOff>false</turnGravityOff>
 </gazebo>

   <gazebo reference="Driving_Right_Back_Link">
     <material>Gazebo/Grey</material>
     <turnGravityOff>false</turnGravityOff>
 </gazebo>


</robot>