<?xml version="1.0" encoding="utf-8"?>
<!-- This URDF was automatically created by SolidWorks to URDF Exporter! Originally created by Stephen Brawner (brawner@gmail.com) 
     Commit Version: 1.6.0-4-g7f85cfe  Build Version: 1.6.7995.38578
     For more information, please see http://wiki.ros.org/sw_urdf_exporter -->
<robot
  name="simplesentry">
  <link
    name="base_link">
    <inertial>
      <origin
        xyz="2.3351E-07 0.00097091 0.015088"
        rpy="0 0 0" />
      <mass
        value="6.9215" />
      <inertia
        ixx="0.27562"
        ixy="3.4079E-06"
        ixz="-1.9782E-08"
        iyy="0.27371"
        iyz="-0.00013381"
        izz="0.54827" />
    </inertial>
    <visual>
      <origin
        xyz="0 0 0"
        rpy="0 0 0" />
      <geometry>
        <mesh
          filename="package://simplesentry/meshes/base_link.STL" />
      </geometry>
      <material
        name="">
        <color
          rgba="1 1 1 1" />
      </material>
    </visual>
    <collision>
      <origin
        xyz="0 0 0"
        rpy="0 0 0" />
      <geometry>
        <mesh
          filename="package://simplesentry/meshes/base_link.STL" />
      </geometry>
    </collision>
  </link>
  <link
    name="Left_Front_Heading_Link">
    <inertial>
      <origin
        xyz="1.38777878078145E-17 0.00190966111212694 4.81482348435591E-09"
        rpy="0 0 0" />
      <mass
        value="0.222633441059111" />
      <inertia
        ixx="0.000282472342479328"
        ixy="8.75872742714748E-20"
        ixz="-1.53578455491772E-11"
        iyy="0.000299326883261327"
        iyz="9.84844083127423E-11"
        izz="0.000282445233574947" />
    </inertial>
    <visual>
      <origin
        xyz="0 0 0"
        rpy="0 0 0" />
      <geometry>
        <mesh
          filename="package://simplesentry/meshes/Left_Front_Heading_Link.STL" />
      </geometry>
      <material
        name="">
        <color
          rgba="1 1 1 1" />
      </material>
    </visual>
    <collision>
      <origin
        xyz="0 0 0"
        rpy="0 0 0" />
      <geometry>
        <mesh
          filename="package://simplesentry/meshes/Left_Front_Heading_Link.STL" />
      </geometry>
    </collision>
  </link>
  <joint
    name="Left_Front_Heading_Joint"
    type="continuous">
    <origin
      xyz="-0.19796 0.19799 -0.02"
      rpy="1.5708 0 3.1416" />
    <parent
      link="base_link" />
    <child
      link="Left_Front_Heading_Link" />
    <axis
      xyz="0 1 0" />
  </joint>
  <link
    name="Left_Front_Driving_Link">
    <inertial>
      <origin
        xyz="0.013 0 0"
        rpy="0 0 0" />
      <mass
        value="0.238918121305504" />
      <inertia
        ixx="0.000373309564539849"
        ixy="2.69533146699333E-20"
        ixz="-5.87276176762981E-21"
        iyy="0.000200113836436801"
        iyz="-1.19966360820855E-36"
        izz="0.000200113836436801" />
    </inertial>
    <visual>
      <origin
        xyz="0 0 0"
        rpy="0 0 0" />
      <geometry>
        <mesh
          filename="package://simplesentry/meshes/Left_Front_Driving_Link.STL" />
      </geometry>
      <material
        name="">
        <color
          rgba="1 1 1 1" />
      </material>
    </visual>
    <collision>
      <origin
        xyz="0 0 0"
        rpy="0 0 0" />
      <geometry>
        <mesh
          filename="package://simplesentry/meshes/Left_Front_Driving_Link.STL" />
      </geometry>
    </collision>
  </link>
  <joint
    name="Left_Front_Driving_Joint"
    type="continuous">
    <origin
      xyz="-0.013 -0.08 0"
      rpy="0 0 0" />
    <parent
      link="Left_Front_Heading_Link" />
    <child
      link="Left_Front_Driving_Link" />
    <axis
      xyz="1 0 0" />
  </joint>
  <link
    name="Left_Back_Heading_Link">
    <inertial>
      <origin
        xyz="0 0.00190966111212694 4.81482347047812E-09"
        rpy="0 0 0" />
      <mass
        value="0.222633441059111" />
      <inertia
        ixx="0.000282472342479328"
        ixy="7.64054506560717E-20"
        ixz="-1.5357845554744E-11"
        iyy="0.000299326883261327"
        iyz="9.84844082347234E-11"
        izz="0.000282445233574947" />
    </inertial>
    <visual>
      <origin
        xyz="0 0 0"
        rpy="0 0 0" />
      <geometry>
        <mesh
          filename="package://simplesentry/meshes/Left_Back_Heading_Link.STL" />
      </geometry>
      <material
        name="">
        <color
          rgba="1 1 1 1" />
      </material>
    </visual>
    <collision>
      <origin
        xyz="0 0 0"
        rpy="0 0 0" />
      <geometry>
        <mesh
          filename="package://simplesentry/meshes/Left_Back_Heading_Link.STL" />
      </geometry>
    </collision>
  </link>
  <joint
    name="Left_Back_Heading_Joint"
    type="continuous">
    <origin
      xyz="-0.19796 -0.19799 -0.02"
      rpy="1.5708 0 3.1416" />
    <parent
      link="base_link" />
    <child
      link="Left_Back_Heading_Link" />
    <axis
      xyz="0 1 0" />
  </joint>
  <link
    name="Left_Back_Driving_Link">
    <inertial>
      <origin
        xyz="0.013 -1.38777878078145E-17 0"
        rpy="0 0 0" />
      <mass
        value="0.238918121305504" />
      <inertia
        ixx="0.000373309564539849"
        ixy="2.69533146699333E-20"
        ixz="-5.87276176762981E-21"
        iyy="0.000200113836436801"
        iyz="-1.19966360820855E-36"
        izz="0.000200113836436801" />
    </inertial>
    <visual>
      <origin
        xyz="0 0 0"
        rpy="0 0 0" />
      <geometry>
        <mesh
          filename="package://simplesentry/meshes/Left_Back_Driving_Link.STL" />
      </geometry>
      <material
        name="">
        <color
          rgba="1 1 1 1" />
      </material>
    </visual>
    <collision>
      <origin
        xyz="0 0 0"
        rpy="0 0 0" />
      <geometry>
        <mesh
          filename="package://simplesentry/meshes/Left_Back_Driving_Link.STL" />
      </geometry>
    </collision>
  </link>
  <joint
    name="Left_Back_Driving_Joint"
    type="continuous">
    <origin
      xyz="-0.013 -0.08 0"
      rpy="0 0 0" />
    <parent
      link="Left_Back_Heading_Link" />
    <child
      link="Left_Back_Driving_Link" />
    <axis
      xyz="1 0 0" />
  </joint>
  <link
    name="Right_Front_Heading_Link">
    <inertial>
      <origin
        xyz="0 0.00190966111212694 4.81482348435591E-09"
        rpy="0 0 0" />
      <mass
        value="0.222633441059111" />
      <inertia
        ixx="0.000282472342479328"
        ixy="4.48324487369313E-20"
        ixz="-1.5357845556234E-11"
        iyy="0.000299326883261327"
        iyz="9.84844083306066E-11"
        izz="0.000282445233574948" />
    </inertial>
    <visual>
      <origin
        xyz="0 0 0"
        rpy="0 0 0" />
      <geometry>
        <mesh
          filename="package://simplesentry/meshes/Right_Front_Heading_Link.STL" />
      </geometry>
      <material
        name="">
        <color
          rgba="1 1 1 1" />
      </material>
    </visual>
    <collision>
      <origin
        xyz="0 0 0"
        rpy="0 0 0" />
      <geometry>
        <mesh
          filename="package://simplesentry/meshes/Right_Front_Heading_Link.STL" />
      </geometry>
    </collision>
  </link>
  <joint
    name="Right_Front_Heading_Joint"
    type="continuous">
    <origin
      xyz="0.19802 0.19799 -0.02"
      rpy="1.5708 0 3.1416" />
    <parent
      link="base_link" />
    <child
      link="Right_Front_Heading_Link" />
    <axis
      xyz="0 1 0" />
  </joint>
  <link
    name="Right_Front_Driving_Link">
    <inertial>
      <origin
        xyz="0.0130000000000001 1.38777878078145E-17 0"
        rpy="0 0 0" />
      <mass
        value="0.238918121305504" />
      <inertia
        ixx="0.00037330956453985"
        ixy="2.69533146699333E-20"
        ixz="-5.87276176762982E-21"
        iyy="0.000200113836436802"
        iyz="3.50231379508061E-36"
        izz="0.000200113836436802" />
    </inertial>
    <visual>
      <origin
        xyz="0 0 0"
        rpy="0 0 0" />
      <geometry>
        <mesh
          filename="package://simplesentry/meshes/Right_Front_Driving_Link.STL" />
      </geometry>
      <material
        name="">
        <color
          rgba="1 1 1 1" />
      </material>
    </visual>
    <collision>
      <origin
        xyz="0 0 0"
        rpy="0 0 0" />
      <geometry>
        <mesh
          filename="package://simplesentry/meshes/Right_Front_Driving_Link.STL" />
      </geometry>
    </collision>
  </link>
  <joint
    name="Right_Front_Driving_Joint"
    type="continuous">
    <origin
      xyz="-0.013 -0.08 0"
      rpy="0 0 0" />
    <parent
      link="Right_Front_Heading_Link" />
    <child
      link="Right_Front_Driving_Link" />
    <axis
      xyz="1 0 0" />
  </joint>
  <link
    name="Right_Back_Heading_Link">
    <inertial>
      <origin
        xyz="0 0.00190966111212693 4.81482345660034E-09"
        rpy="0 0 0" />
      <mass
        value="0.222633441059111" />
      <inertia
        ixx="0.000282472342479328"
        ixy="2.46591602827902E-20"
        ixz="-1.53578455521235E-11"
        iyy="0.000299326883261327"
        iyz="9.84844082287288E-11"
        izz="0.000282445233574948" />
    </inertial>
    <visual>
      <origin
        xyz="0 0 0"
        rpy="0 0 0" />
      <geometry>
        <mesh
          filename="package://simplesentry/meshes/Right_Back_Heading_Link.STL" />
      </geometry>
      <material
        name="">
        <color
          rgba="1 1 1 1" />
      </material>
    </visual>
    <collision>
      <origin
        xyz="0 0 0"
        rpy="0 0 0" />
      <geometry>
        <mesh
          filename="package://simplesentry/meshes/Right_Back_Heading_Link.STL" />
      </geometry>
    </collision>
  </link>
  <joint
    name="Right_Back_Heading_Joint"
    type="continuous">
    <origin
      xyz="0.19802 -0.19799 -0.02"
      rpy="1.5708 0 3.1416" />
    <parent
      link="base_link" />
    <child
      link="Right_Back_Heading_Link" />
    <axis
      xyz="0 1 0" />
  </joint>
  <link
    name="Right_Back_Driving_Link">
    <inertial>
      <origin
        xyz="0.0130000000000001 1.38777878078145E-17 0"
        rpy="0 0 0" />
      <mass
        value="0.238918121305504" />
      <inertia
        ixx="0.00037330956453985"
        ixy="2.69533146699333E-20"
        ixz="-5.87276176762982E-21"
        iyy="0.000200113836436802"
        iyz="3.50231379508061E-36"
        izz="0.000200113836436802" />
    </inertial>
    <visual>
      <origin
        xyz="0 0 0"
        rpy="0 0 0" />
      <geometry>
        <mesh
          filename="package://simplesentry/meshes/Right_Back_Driving_Link.STL" />
      </geometry>
      <material
        name="">
        <color
          rgba="1 1 1 1" />
      </material>
    </visual>
    <collision>
      <origin
        xyz="0 0 0"
        rpy="0 0 0" />
      <geometry>
        <mesh
          filename="package://simplesentry/meshes/Right_Back_Driving_Link.STL" />
      </geometry>
    </collision>
  </link>
  <joint
    name="Right_Back_Driving_Joint"
    type="continuous">
    <origin
      xyz="-0.013 -0.08 0"
      rpy="0 0 0" />
    <parent
      link="Right_Back_Heading_Link" />
    <child
      link="Right_Back_Driving_Link" />
    <axis
      xyz="1 0 0" />
  </joint>
  <link
    name="Yaw_Link">
    <inertial>
      <origin
        xyz="-0.000382893451164545 -0.00504114565025875 0.10698800887067"
        rpy="0 0 0" />
      <mass
        value="10.3493804906921" />
      <inertia
        ixx="0.149218627722498"
        ixy="0.000307277659773353"
        ixz="0.000417481332867916"
        iyy="0.153240882832408"
        iyz="0.00549652703343564"
        izz="0.0747791685099092" />
    </inertial>
    <visual>
      <origin
        xyz="0 0 0"
        rpy="0 0 0" />
      <geometry>
        <mesh
          filename="package://simplesentry/meshes/Yaw_Link.STL" />
      </geometry>
      <material
        name="">
        <color
          rgba="1 1 1 1" />
      </material>
    </visual>
    <collision>
      <origin
        xyz="0 0 0"
        rpy="0 0 0" />
      <geometry>
        <mesh
          filename="package://simplesentry/meshes/Yaw_Link.STL" />
      </geometry>
    </collision>
  </link>
  <joint
    name="Yaw_Joint"
    type="continuous">
    <origin
      xyz="3.2896E-05 0 0.09"
      rpy="0 0 0" />
    <parent
      link="base_link" />
    <child
      link="Yaw_Link" />
    <axis
      xyz="0 0 -1" />
  </joint>
  <link
    name="Pitch_Link">
    <inertial>
      <origin
        xyz="-0.00896541138540202 0.0169097992328111 0.118037914910391"
        rpy="0 0 0" />
      <mass
        value="1.64398229715026" />
      <inertia
        ixx="0.00813629688390596"
        ixy="6.73637561202836E-05"
        ixz="0.000472677544890049"
        iyy="0.00801271880973763"
        iyz="-0.00088690601815744"
        izz="0.00194896236802813" />
    </inertial>
    <visual>
      <origin
        xyz="0 0 0"
        rpy="0 0 0" />
      <geometry>
        <mesh
          filename="package://simplesentry/meshes/Pitch_Link.STL" />
      </geometry>
      <material
        name="">
        <color
          rgba="1 1 1 1" />
      </material>
    </visual>
    <collision>
      <origin
        xyz="0 0 0"
        rpy="0 0 0" />
      <geometry>
        <mesh
          filename="package://simplesentry/meshes/Pitch_Link.STL" />
      </geometry>
    </collision>
  </link>
  <joint
    name="Pitch_Joint"
    type="continuous">
    <origin
      xyz="0.0015147 0.019943 0.25044"
      rpy="1.5708 0 3.1416" />
    <parent
      link="Yaw_Link" />
    <child
      link="Pitch_Link" />
    <axis
      xyz="0.99713 0 0.075736" />
  </joint>
  <link
    name="Laser_Imu_link">
    <inertial>
      <origin
        xyz="-6.93889390390723E-17 -3.46944695195361E-16 0.0255156136079572"
        rpy="0 0 0" />
      <mass
        value="0.12185840734641" />
      <inertia
        ixx="5.06895795583208E-05"
        ixy="-1.44560289664713E-21"
        ixz="1.27975279084585E-21"
        iyy="5.06895795583208E-05"
        iyz="5.69889882490571E-21"
        izz="5.19262537006539E-05" />
    </inertial>
    <visual>
      <origin
        xyz="0 0 0"
        rpy="0 0 0" />
      <geometry>
        <mesh
          filename="package://simplesentry/meshes/Laser_Imu_link.STL" />
      </geometry>
      <material
        name="">
        <color
          rgba="1 1 1 1" />
      </material>
    </visual>
    <collision>
      <origin
        xyz="0 0 0"
        rpy="0 0 0" />
      <geometry>
        <mesh
          filename="package://simplesentry/meshes/Laser_Imu_link.STL" />
      </geometry>
    </collision>
  </link>
  <joint
    name="Laser_Imu_Joint"
    type="fixed">
    <origin
      xyz="0 0 0"
      rpy="0 0 0" />
    <parent
      link="Yaw_Link" />
    <child
      link="Laser_Imu_link" />
    <axis
      xyz="0 0 0" />
  </joint>
</robot>